Workbook

Sheet ResFind.Gene.count
B1: ALB.17 | C1: AUS.18 | D1: AUS.18a | E1: AUT.70 | F1: BGR.66 | G1: BRA.53 | H1: BRA.53a | I1: BWA.19 | J1: CAN.22 | K1: CAN.22a | L1: CAN.22b | M1: CAN.22c | N1: CHE.67 | O1: CHN.64 | P1: CIV.13 | Q1: COL.2 | R1: CZE.23 | S1: DEU.27 | T1: DNK.71_RA | U1: DNK.71_RD | V1: DNK.71_RL | W1: ECU.14 | X1: ECU.14a | Y1: ESP.75 | Z1: ETH.24 | AA1: FIN.25 | AB1: GEO.59 | AC1: GHA.4 | AD1: HRV.68 | AE1: HUN.61 | AF1: IND.11 | AG1: IRL.69 | AH1: IRN.12 | AI1: ISL.28 | AJ1: ISR.29 | AK1: ITA.30 | AL1: KAZ.6 | AM1: KEN.72 | AN1: KHM.21 | AO1: LKA.40 | AP1: LUX.32 | AQ1: LVA.31 | AR1: MDA.65 | AS1: MKD.62 | AT1: MLT.63 | AU1: MYS.54 | AV1: NGA.50 | AW1: NLD.43 | AX1: NOR.34 | AY1: NPL.33 | AZ1: NZL.56 | BA1: PAK.7 | BB1: PER.35 | BC1: POL.36 | BD1: SEN.8 | BE1: SGP.52 | BF1: SRB.37 | BG1: SVK.9 | BH1: SVN.38 | BI1: SWE.41 | BJ1: SWE.41a | BK1: TGO.44 | BL1: TUR.46 | BM1: TZA.15 | BN1: USA.74 | BO1: USA.74a | BP1: USA.74b | BQ1: USA.74c | BR1: USA.74d | BS1: USA.74e | BT1: USA.74f | BU1: USA.74g | BV1: USA.74h | BW1: USA.74i | BX1: VNM.48 | BY1: XK.60 | BZ1: ZAF.39 | CA1: ZMB.49 | CB1: ZMB.49b
A2: ampH_ampS | B2: 4 | C2: 1 | D2: 0 | E2: 4 | F2: 7 | G2: 0 | H2: 1 | I2: 0 | J2: 1 | K2: 1 | L2: 0 | M2: 1 | N2: 0 | O2: 0 | P2: 0 | Q2: 0 | R2: 1 | S2: 0 | T2: 5 | U2: 3 | V2: 3 | W2: 1 | X2: 0 | Y2: 5 | Z2: 0 | AA2: 2 | AB2: 8 | AC2: 0 | AD2: 2 | AE2: 0 | AF2: 1 | AG2: 9 | AH2: 3 | AI2: 8 | AJ2: 0 | AK2: 2 | AL2: 1 | AM2: 0 | AN2: 0 | AO2: 0 | AP2: 3 | AQ2: 0 | AR2: 4 | AS2: 4 | AT2: 17 | AU2: 0 | AV2: 1 | AW2: 5 | AX2: 3 | AY2: 1 | AZ2: 1 | BA2: 4 | BB2: 1 | BC2: 1 | BD2: 0 | BE2: 0 | BF2: 2 | BG2: 3 | BH2: 2 | BI2: 1 | BJ2: 0 | BK2: 69 | BL2: 6 | BM2: 19 | BN2: 2 | BO2: 0 | BP2: 2 | BQ2: 0 | BR2: 6 | BS2: 1 | BT2: 0 | BU2: 2 | BV2: 14 | BW2: 0 | BX2: 89 | BY2: 2 | BZ2: 1 | CA2: 4 | CB2: 9
A3: ant(3'')-Ih-aac(6')-IId | B3: 242 | C3: 166 | D3: 104 | E3: 205 | F3: 382 | G3: 230 | H3: 128 | I3: 197 | J3: 36 | K3: 21 | L3: 118 | M3: 31 | N3: 192 | O3: 111 | P3: 240 | Q3: 11 | R3: 116 | S3: 138 | T3: 178 | U3: 262 | V3: 138 | W3: 134 | X3: 267 | Y3: 540 | Z3: 683 | AA3: 117 | AB3: 43 | AC3: 37 | AD3: 255 | AE3: 13 | AF3: 135 | AG3: 162 | AH3: 492 | AI3: 145 | AJ3: 115 | AK3: 208 | AL3: 163 | AM3: 238 | AN3: 78 | AO3: 25 | AP3: 615 | AQ3: 95 | AR3: 216 | AS3: 516 | AT3: 307 | AU3: 245 | AV3: 271 | AW3: 24 | AX3: 137 | AY3: 44 | AZ3: 7 | BA3: 189 | BB3: 553 | BC3: 93 | BD3: 135 | BE3: 154 | BF3: 257 | BG3: 159 | BH3: 106 | BI3: 114 | BJ3: 76 | BK3: 78 | BL3: 127 | BM3: 538 | BN3: 21 | BO3: 24 | BP3: 119 | BQ3: 148 | BR3: 73 | BS3: 204 | BT3: 122 | BU3: 229 | BV3: 133 | BW3: 192 | BX3: 153 | BY3: 477 | BZ3: 219 | CA3: 372 | CB3: 1017
A4: ant(4')-IIb | B4: 0 | C4: 0 | D4: 0 | E4: 0 | F4: 0 | G4: 0 | H4: 0 | I4: 0 | J4: 0 | K4: 0 | L4: 0 | M4: 0 | N4: 0 | O4: 0 | P4: 0 | Q4: 0 | R4: 0 | S4: 0 | T4: 0 | U4: 0 | V4: 0 | W4: 0 | X4: 0 | Y4: 0 | Z4: 0 | AA4: 0 | AB4: 0 | AC4: 0 | AD4: 0 | AE4: 0 | AF4: 3 | AG4: 0 | AH4: 0 | AI4: 0 | AJ4: 0 | AK4: 0 | AL4: 0 | AM4: 0 | AN4: 0 | AO4: 0 | AP4: 0 | AQ4: 0 | AR4: 0 | AS4: 0 | AT4: 0 | AU4: 0 | AV4: 0 | AW4: 0 | AX4: 0 | AY4: 0 | AZ4: 0 | BA4: 0 | BB4: 0 | BC4: 0 | BD4: 0 | BE4: 0 | BF4: 0 | BG4: 0 | BH4: 0 | BI4: 0 | BJ4: 0 | BK4: 0 | BL4: 0 | BM4: 0 | BN4: 0 | BO4: 0 | BP4: 0 | BQ4: 0 | BR4: 0 | BS4: 0 | BT4: 0 | BU4: 0 | BV4: 0 | BW4: 0 | BX4: 0 | BY4: 0 | BZ4: 0 | CA4: 0 | CB4: 0
A5: ant(6)-Ia | B5: 1 | C5: 1 | D5: 23 | E5: 5 | F5: 3 | G5: 5 | H5: 1 | I5: 3 | J5: 3 | K5: 0 | L5: 37 | M5: 4 | N5: 2 | O5: 4 | P5: 8 | Q5: 3 | R5: 1 | S5: 4 | T5: 6 | U5: 9 | V5: 9 | W5: 0 | X5: 4 | Y5: 19 | Z5: 11 | AA5: 47 | AB5: 0 | AC5: 5 | AD5: 2 | AE5: 0 | AF5: 29 | AG5: 4 | AH5: 3 | AI5: 1 | AJ5: 0 | AK5: 6 | AL5: 84 | AM5: 30 | AN5: 8 | AO5: 2 | AP5: 3 | AQ5: 7 | AR5: 15 | AS5: 12 | AT5: 14 | AU5: 44 | AV5: 9 | AW5: 2 | AX5: 3 | AY5: 98 | AZ5: 0 | BA5: 18 | BB5: 8 | BC5: 23 | BD5: 4 | BE5: 16 | BF5: 12 | BG5: 4 | BH5: 16 | BI5: 10 | BJ5: 9 | BK5: 204 | BL5: 1 | BM5: 12 | BN5: 2 | BO5: 16 | BP5: 13 | BQ5: 11 | BR5: 25 | BS5: 19 | BT5: 4 | BU5: 22 | BV5: 14 | BW5: 2 | BX5: 3 | BY5: 3 | BZ5: 17 | CA5: 7 | CB5: 10
A6: ant(6)-Ib | B6: 2 | C6: 1 | D6: 2 | E6: 6 | F6: 4 | G6: 0 | H6: 2 | I6: 0 | J6: 8 | K6: 2 | L6: 23 | M6: 11 | N6: 0 | O6: 8 | P6: 14 | Q6: 0 | R6: 3 | S6: 14 | T6: 4 | U6: 12 | V6: 4 | W6: 0 | X6: 0 | Y6: 10 | Z6: 7 | AA6: 6 | AB6: 0 | AC6: 2 | AD6: 0 | AE6: 2 | AF6: 27 | AG6: 2 | AH6: 2 | AI6: 0 | AJ6: 0 | AK6: 10 | AL6: 1 | AM6: 12 | AN6: 6 | AO6: 1 | AP6: 5 | AQ6: 3 | AR6: 2 | AS6: 10 | AT6: 26 | AU6: 4 | AV6: 2 | AW6: 7 | AX6: 0 | AY6: 29 | AZ6: 1 | BA6: 20 | BB6: 6 | BC6: 100 | BD6: 0 | BE6: 0 | BF6: 14 | BG6: 4 | BH6: 17 | BI6: 7 | BJ6: 8 | BK6: 11 | BL6: 0 | BM6: 4 | BN6: 14 | BO6: 21 | BP6: 5 | BQ6: 4 | BR6: 3 | BS6: 3 | BT6: 1 | BU6: 7 | BV6: 3 | BW6: 4 | BX6: 0 | BY6: 4 | BZ6: 1 | CA6: 8 | CB6: 12
A7: aph(2'')-Ib | B7: 4 | C7: 0 | D7: 0 | E7: 10 | F7: 11 | G7: 1 | H7: 0 | I7: 0 | J7: 3 | K7: 0 | L7: 1 | M7: 0 | N7: 2 | O7: 1 | P7: 0 | Q7: 0 | R7: 1 | S7: 0 | T7: 0 | U7: 0 | V7: 2 | W7: 1 | X7: 3 | Y7: 3 | Z7: 0 | AA7: 3 | AB7: 0 | AC7: 0 | AD7: 4 | AE7: 0 | AF7: 3 | AG7: 0 | AH7: 2 | AI7: 0 | AJ7: 1 | AK7: 0 | AL7: 0 | AM7: 0 | AN7: 0 | AO7: 0 | AP7: 0 | AQ7: 3 | AR7: 4 | AS7: 15 | AT7: 3 | AU7: 0 | AV7: 0 | AW7: 0 | AX7: 0 | AY7: 0 | AZ7: 0 | BA7: 4 | BB7: 2 | BC7: 0 | BD7: 0 | BE7: 0 | BF7: 51 | BG7: 3 | BH7: 14 | BI7: 1 | BJ7: 0 | BK7: 0 | BL7: 0 | BM7: 0 | BN7: 0 | BO7: 1 | BP7: 0 | BQ7: 0 | BR7: 3 | BS7: 4 | BT7: 2 | BU7: 3 | BV7: 1 | BW7: 0 | BX7: 0 | BY7: 12 | BZ7: 0 | CA7: 0 | CB7: 2
A8: aph(2'')-Ic | B8: 6 | C8: 1 | D8: 0 | E8: 0 | F8: 0 | G8: 0 | H8: 0 | I8: 0 | J8: 0 | K8: 0 | L8: 0 | M8: 0 | N8: 0 | O8: 0 | P8: 0 | Q8: 0 | R8: 0 | S8: 1 | T8: 0 | U8: 0 | V8: 1 | W8: 0 | X8: 0 | Y8: 32 | Z8: 0 | AA8: 0 | AB8: 0 | AC8: 0 | AD8: 0 | AE8: 0 | AF8: 0 | AG8: 2 | AH8: 0 | AI8: 0 | AJ8: 0 | AK8: 0 | AL8: 0 | AM8: 0 | AN8: 0 | AO8: 0 | AP8: 0 | AQ8: 0 | AR8: 1 | AS8: 0 | AT8: 1 | AU8: 0 | AV8: 0 | AW8: 0 | AX8: 0 | AY8: 0 | AZ8: 0 | BA8: 0 | BB8: 1 | BC8: 0 | BD8: 0 | BE8: 0 | BF8: 0 | BG8: 0 | BH8: 1 | BI8: 0 | BJ8: 0 | BK8: 0 | BL8: 0 | BM8: 0 | BN8: 0 | BO8: 12 | BP8: 1 | BQ8: 0 | BR8: 0 | BS8: 0 | BT8: 0 | BU8: 1 | BV8: 0 | BW8: 17 | BX8: 0 | BY8: 0 | BZ8: 0 | CA8: 0 | CB8: 0
A9: aph(2'')-Id_aph(2'')-Ie | B9: 0 | C9: 15 | D9: 8 | E9: 0 | F9: 0 | G9: 16 | H9: 0 | I9: 0 | J9: 0 | K9: 0 | L9: 0 | M9: 0 | N9: 0 | O9: 9 | P9: 0 | Q9: 0 | R9: 0 | S9: 0 | T9: 0 | U9: 0 | V9: 2 | W9: 0 | X9: 2 | Y9: 0 | Z9: 0 | AA9: 0 | AB9: 0 | AC9: 0 | AD9: 0 | AE9: 0 | AF9: 0 | AG9: 0 | AH9: 8 | AI9: 0 | AJ9: 0 | AK9: 1 | AL9: 8 | AM9: 0 | AN9: 0 | AO9: 1 | AP9: 0 | AQ9: 0 | AR9: 1 | AS9: 0 | AT9: 2 | AU9: 0 | AV9: 0 | AW9: 0 | AX9: 0 | AY9: 3 | AZ9: 0 | BA9: 0 | BB9: 0 | BC9: 0 | BD9: 0 | BE9: 0 | BF9: 0 | BG9: 0 | BH9: 10 | BI9: 0 | BJ9: 0 | BK9: 5 | BL9: 0 | BM9: 0 | BN9: 0 | BO9: 1 | BP9: 0 | BQ9: 4 | BR9: 3 | BS9: 1 | BT9: 2 | BU9: 8 | BV9: 1 | BW9: 0 | BX9: 0 | BY9: 0 | BZ9: 1 | CA9: 1 | CB9: 0
A10: aph(3'')-Ic | B10: 0 | C10: 0 | D10: 0 | E10: 0 | F10: 0 | G10: 0 | H10: 0 | I10: 0 | J10: 0 | K10: 0 | L10: 0 | M10: 0 | N10: 0 | O10: 0 | P10: 0 | Q10: 0 | R10: 0 | S10: 0 | T10: 0 | U10: 0 | V10: 0 | W10: 0 | X10: 0 | Y10: 0 | Z10: 0 | AA10: 0 | AB10: 0 | AC10: 0 | AD10: 0 | AE10: 0 | AF10: 0 | AG10: 0 | AH10: 0 | AI10: 0 | AJ10: 0 | AK10: 0 | AL10: 0 | AM10: 0 | AN10: 0 | AO10: 0 | AP10: 0 | AQ10: 0 | AR10: 0 | AS10: 0 | AT10: 0 | AU10: 0 | AV10: 0 | AW10: 0 | AX10: 0 | AY10: 0 | AZ10: 0 | BA10: 0 | BB10: 0 | BC10: 0 | BD10: 1 | BE10: 0 | BF10: 0 | BG10: 0 | BH10: 0 | BI10: 0 | BJ10: 0 | BK10: 0 | BL10: 0 | BM10: 0 | BN10: 0 | BO10: 0 | BP10: 0 | BQ10: 0 | BR10: 0 | BS10: 0 | BT10: 0 | BU10: 1 | BV10: 0 | BW10: 0 | BX10: 0 | BY10: 0 | BZ10: 0 | CA10: 0 | CB10: 0
A11: aph(3')-Ia_aph(3')-Ic | B11: 21 | C11: 12 | D11: 7 | E11: 10 | F11: 8 | G11: 32 | H11: 1 | I11: 6 | J11: 3 | K11: 1 | L11: 8 | M11: 0 | N11: 17 | O11: 4 | P11: 12 | Q11: 0 | R11: 2 | S11: 14 | T11: 3 | U11: 2 | V11: 2 | W11: 14 | X11: 6 | Y11: 25 | Z11: 12 | AA11: 21 | AB11: 16 | AC11: 0 | AD11: 1 | AE11: 0 | AF11: 10 | AG11: 9 | AH11: 24 | AI11: 5 | AJ11: 5 | AK11: 12 | AL11: 10 | AM11: 63 | AN11: 480 | AO11: 2 | AP11: 5 | AQ11: 3 | AR11: 4 | AS11: 9 | AT11: 82 | AU11: 23 | AV11: 12 | AW11: 2 | AX11: 4 | AY11: 10 | AZ11: 2 | BA11: 10 | BB11: 23 | BC11: 4 | BD11: 9 | BE11: 17 | BF11: 3 | BG11: 13 | BH11: 5 | BI11: 3 | BJ11: 0 | BK11: 0 | BL11: 14 | BM11: 37 | BN11: 1 | BO11: 4 | BP11: 11 | BQ11: 20 | BR11: 20 | BS11: 106 | BT11: 7 | BU11: 24 | BV11: 2 | BW11: 7 | BX11: 69 | BY11: 16 | BZ11: 2 | CA11: 27 | CB11: 45
A12: aph(3')-Ib | B12: 3 | C12: 3 | D12: 3 | E12: 0 | F12: 0 | G12: 0 | H12: 1 | I12: 0 | J12: 0 | K12: 0 | L12: 0 | M12: 0 | N12: 0 | O12: 1 | P12: 113 | Q12: 0 | R12: 0 | S12: 0 | T12: 2 | U12: 2 | V12: 0 | W12: 0 | X12: 1 | Y12: 0 | Z12: 1 | AA12: 1 | AB12: 12 | AC12: 1 | AD12: 0 | AE12: 0 | AF12: 3 | AG12: 0 | AH12: 2 | AI12: 1 | AJ12: 0 | AK12: 2 | AL12: 0 | AM12: 5 | AN12: 26 | AO12: 3 | AP12: 0 | AQ12: 0 | AR12: 2 | AS12: 3 | AT12: 1 | AU12: 2 | AV12: 36 | AW12: 0 | AX12: 1 | AY12: 9 | AZ12: 0 | BA12: 0 | BB12: 2 | BC12: 0 | BD12: 5 | BE12: 3 | BF12: 0 | BG12: 1 | BH12: 0 | BI12: 0 | BJ12: 0 | BK12: 3 | BL12: 3 | BM12: 105 | BN12: 1 | BO12: 4 | BP12: 1 | BQ12: 1 | BR12: 0 | BS12: 0 | BT12: 1 | BU12: 1 | BV12: 0 | BW12: 0 | BX12: 3 | BY12: 1 | BZ12: 0 | CA12: 1 | CB12: 1
A13: aph(3')-Id | B13: 0 | C13: 0 | D13: 0 | E13: 0 | F13: 0 | G13: 0 | H13: 0 | I13: 0 | J13: 0 | K13: 0 | L13: 0 | M13: 0 | N13: 0 | O13: 0 | P13: 0 | Q13: 0 | R13: 0 | S13: 0 | T13: 0 | U13: 0 | V13: 0 | W13: 0 | X13: 0 | Y13: 0 | Z13: 0 | AA13: 0 | AB13: 0 | AC13: 0 | AD13: 0 | AE13: 0 | AF13: 0 | AG13: 0 | AH13: 0 | AI13: 0 | AJ13: 0 | AK13: 0 | AL13: 0 | AM13: 0 | AN13: 0 | AO13: 0 | AP13: 0 | AQ13: 1 | AR13: 0 | AS13: 0 | AT13: 0 | AU13: 0 | AV13: 0 | AW13: 0 | AX13: 0 | AY13: 0 | AZ13: 0 | BA13: 0 | BB13: 0 | BC13: 0 | BD13: 0 | BE13: 0 | BF13: 0 | BG13: 0 | BH13: 0 | BI13: 0 | BJ13: 0 | BK13: 0 | BL13: 0 | BM13: 0 | BN13: 0 | BO13: 0 | BP13: 0 | BQ13: 0 | BR13: 0 | BS13: 0 | BT13: 0 | BU13: 0 | BV13: 0 | BW13: 0 | BX13: 0 | BY13: 0 | BZ13: 0 | CA13: 0 | CB13: 0
... A409: aadK | B409: 0 | C409: 0 | D409: 0 | E409: 0 | F409: 0 | G409: 0 | H409: 0 | I409: 0 | J409: 0 | K409: 0 | L409: 0 | M409: 0 | N409: 0 | O409: 0 | P409: 0 | Q409: 0 | R409: 0 | S409: 0 | T409: 0 | U409: 0 | V409: 0 | W409: 0 | X409: 0 | Y409: 0 | Z409: 0 | AA409: 0 | AB409: 0 | AC409: 0 | AD409: 0 | AE409: 0 | AF409: 0 | AG409: 0 | AH409: 0 | AI409: 0 | AJ409: 0 | AK409: 0 | AL409: 0 | AM409: 0 | AN409: 1 | AO409: 0 | AP409: 0 | AQ409: 0 | AR409: 0 | AS409: 0 | AT409: 0 | AU409: 0 | AV409: 0 | AW409: 0 | AX409: 0 | AY409: 0 | AZ409: 0 | BA409: 0 | BB409: 0 | BC409: 0 | BD409: 1 | BE409: 0 | BF409: 0 | BG409: 0 | BH409: 0 | BI409: 0 | BJ409: 0 | BK409: 0 | BL409: 0 | BM409: 0 | BN409: 0 | BO409: 0 | BP409: 0 | BQ409: 0 | BR409: 0 | BS409: 0 | BT409: 0 | BU409: 0 | BV409: 0 | BW409: 0 | BX409: 0 | BY409: 1 | BZ409: 0 | CA409: 0 | CB409: 0

Sheet GS.ResFind.Gene.FPKM
A1: Site | B1: ALB.17 | C1: AUS.18 | D1: AUS.18a | E1: AUT.70 | F1: BGR.66 | G1: BRA.53 | H1: BRA.53a | I1: BWA.19 | J1: CAN.22 | K1: CAN.22a | L1: CAN.22b | M1: CAN.22c | N1: CHE.67 | O1: CHN.64 | P1: CIV.13 | Q1: COL.2 | R1: CZE.23 | S1: DEU.27 | T1: DNK.71_RA | U1: DNK.71_RD | V1: DNK.71_RL | W1: ECU.14 | X1: ECU.14a | Y1: ESP.75 | Z1: ETH.24 | AA1: FIN.25 | AB1: GEO.59 | AC1: GHA.4 | AD1: HRV.68 | AE1: HUN.61 | AF1: IND.11 | AG1: IRL.69 | AH1: IRN.12 | AI1: ISL.28 | AJ1: ISR.29 | AK1: ITA.30 | AL1: KAZ.6 | AM1: KEN.72 | AN1: KHM.21 | AO1: LKA.40 | AP1: LUX.32 | AQ1: LVA.31 | AR1: MDA.65 | AS1: MKD.62 | AT1: MLT.63 | AU1: MYS.54 | AV1: NGA.50 | AW1: NLD.43 | AX1: NOR.34 | AY1: NPL.33 | AZ1: NZL.56 | BA1: PAK.7 | BB1: PER.35 | BC1: POL.36 | BD1: SEN.8 | BE1: SGP.52 | BF1: SRB.37 | BG1: SVK.9 | BH1: SVN.38 | BI1: SWE.41 | BJ1: SWE.41a | BK1: TGO.44 | BL1: TUR.46 | BM1: TZA.15 | BN1: USA.74 | BO1: USA.74a | BP1: USA.74b | BQ1: USA.74c | BR1: USA.74d | BS1: USA.74e | BT1: USA.74f | BU1: USA.74g | BV1: USA.74h | BW1: USA.74i | BX1: VNM.48 | BY1: XK.60 | BZ1: ZAF.39 | CA1: ZMB.49 | CB1: ZMB.49b
A2: Country | B2: =LEFT(B1,3) -> ALB | C2: =LEFT(C1,3) -> AUS | D2: =LEFT(D1,3) -> AUS | E2: =LEFT(E1,3) -> AUT | F2: =LEFT(F1,3) -> BGR | G2: =LEFT(G1,3) -> BRA | H2: =LEFT(H1,3) -> BRA | I2: =LEFT(I1,3) -> BWA | ... CB2: =LEFT(CB1,3) -> ZMB
A3: Country Full | B3: =VLOOKUP(B1,'Sample count'!$F$2:$J$230,2) -> Albania | C3: =VLOOKUP(C1,'Sample count'!$F$2:$J$230,2) -> Australia | D3: =VLOOKUP(D1,'Sample count'!$F$2:$J$230,2) -> Australia | E3: =VLOOKUP(E1,'Sample count'!$F$2:$J$230,2) -> Austria | F3: =VLOOKUP(F1,'Sample count'!$F$2:$J$230,2) -> Bulgaria | G3: =VLOOKUP(G1,'Sample count'!$F$2:$J$230,2) -> Brasil | H3: =VLOOKUP(H1,'Sample count'!$F$2:$J$230,2) -> Brasil | I3: =VLOOKUP(I1,'Sample count'!$F$2:$J$230,2) -> Botswana | ... CB3: =VLOOKUP(CB1,'Sample count'!$F$2:$J$230,2) -> Zambia
A4: Continent | B4: =VLOOKUP(B1,'Sample count'!$F$2:$J$230,3) -> Europe | C4: =VLOOKUP(C1,'Sample count'!$F$2:$J$230,3) -> Oceania | D4: =VLOOKUP(D1,'Sample count'!$F$2:$J$230,3) -> Oceania | E4: =VLOOKUP(E1,'Sample count'!$F$2:$J$230,3) -> Europe | F4: =VLOOKUP(F1,'Sample count'!$F$2:$J$230,3) -> Europe | G4: =VLOOKUP(G1,'Sample count'!$F$2:$J$230,3) -> South America | H4: =VLOOKUP(H1,'Sample count'!$F$2:$J$230,3) -> South America | I4: =VLOOKUP(I1,'Sample count'!$F$2:$J$230,3) -> Africa | ... CB4: =VLOOKUP(CB1,'Sample count'!$F$2:$J$230,3) -> Africa
A5: ampH_ampS | B5: 0.18449388 | C5: 0.074911162 | D5: 0 | E5: 0.23798391 | F5: 0.35665611 | G5: 0 | H5: 0.16768548 | I5: 0 | J5: 0.10689862 | K5: 0.31259795 | L5: 0 | M5: 0.14006813 | N5: 0 | O5: 0 | P5: 0 | Q5: 0 | R5: 0.087099048 | S5: 0 | T5: 0.51527987 | U5: 0.18694138 | V5: 0.42377542 | W5: 0.060710632 | X5: 0 | Y5: 0.27429544 | Z5: 0 | AA5: 0.20720832 | AB5: 0.3498887 | AC5: 0 | AD5: 0.21232035 | AE5: 0 | AF5: 0.081635975 | AG5: 0.50053478 | AH5: 0.24575594 | AI5: 0.56410721 | AJ5: 0 | AK5: 0.16107088 | AL5: 0.098457957 | AM5: 0 | AN5: 0 | AO5: 0 | AP5: 0.23856765 | AQ5: 0 | AR5: 0.17219301 | AS5: 0.2219191 | AT5: 1.0708316 | AU5: 0 | AV5: 0.13843049 | AW5: 0.78333783 | AX5: 0.23560801 | AY5: 0.11331244 | AZ5: 0.051117796 | BA5: 0.47541772 | BB5: 0.13016886 | BC5: 0.16387505 | BD5: 0 | BE5: 0 | BF5: 0.16360209 | BG5: 0.35722159 | BH5: 0.15930114 | BI5: 0.089568822 | BJ5: 0 | BK5: 10.391508 | BL5: 0.40705775 | BM5: 1.1981785 | BN5: 0.40322857 | BO5: 0 | BP5: 0.1890553 | BQ5: 0 | BR5: 0.34924998 | BS5: 0.064029829 | BT5: 0 | BU5: 0.15802562 | BV5: 0.99991085 | BW5: 0 | BX5: 3.3191764 | BY5: 0.14689887 | BZ5: 0.1889723 | CA5: 0.37208096 | CB5: 0.23024741
A6: ant(3'')-Ih-aac(6')-IId | B6: 10.184536 | C6: 11.035579 | D6: 7.3111131 | E6: 10.651436 | F6: 17.378314 | G6: 18.325873 | H6: 17.195345 | I6: 31.787509 | J6: 3.3799434 | K6: 5.8231545 | L6: 4.1182975 | M6: 3.9814336 | N6: 17.487902 | O6: 23.89249 | P6: 23.054297 | Q6: 2.8164902 | R6: 9.0668044 | S6: 14.474704 | T6: 16.517124 | U6: 14.470688 | V6: 17.104399 | W6: 7.4201853 | X6: 63.725241 | Y6: 27.173432 | Z6: 45.067487 | AA6: 10.593565 | AB6: 1.8119603 | AC6: 14.483666 | AD6: 24.489843 | AE6: 21.459095 | AF6: 10.707911 | AG6: 7.7974275 | AH6: 38.46328 | AI6: 8.734565 | AJ6: 28.428138 | AK6: 15.022596 | AL6: 14.221104 | AM6: 14.953039 | AN6: 12.87806 | AO6: 0.8661145 | AP6: 43.767121 | AQ6: 18.021474 | AR6: 8.6212984 | AS6: 25.556781 | AT6: 17.86477 | AU6: 15.31941 | AV6: 33.611398 | AW6: 3.7272743 | AX6: 9.9253332 | AY6: 4.609963 | AZ6: 0.31741179 | BA6: 19.90978 | BB6: 64.523508 | BC6: 13.639467 | BD6: 4.7880611 | BE6: 24.472996 | BF6: 18.663547 | BG6: 17.222024 | BH6: 7.8474815 | BI6: 9.3972102 | BJ6: 4.7559036 | BK6: 10.533504 | BL6: 7.5621944 | BM6: 29.697622 | BN6: 3.6847728 | BO6: 2.0901515 | BP6: 9.8213469 | BQ6: 13.77163 | BR6: 3.9315983 | BS6: 11.271979 | BT6: 14.361335 | BU6: 15.314092 | BV6: 8.5212032 | BW6: 30.304926 | BX6: 4.8219143 | BY6: 30.234653 | BZ6: 36.546674 | CA6: 30.901498 | CB6: 23.635848
A7: ant(4')-IIb | B7: 0 | C7: 0 | D7: 0 | E7: 0 | F7: 0 | G7: 0 | H7: 0 | I7: 0 | J7: 0 | K7: 0 | L7: 0 | M7: 0 | N7: 0 | O7: 0 | P7: 0 | Q7: 0 | R7: 0 | S7: 0 | T7: 0 | U7: 0 | V7: 0 | W7: 0 | X7: 0 | Y7: 0 | Z7: 0 | AA7: 0 | AB7: 0 | AC7: 0 | AD7: 0 | AE7: 0 | AF7: 0.25754206 | AG7: 0 | AH7: 0 | AI7: 0 | AJ7: 0 | AK7: 0 | AL7: 0 | AM7: 0 | AN7: 0 | AO7: 0 | AP7: 0 | AQ7: 0 | AR7: 0 | AS7: 0 | AT7: 0 | AU7: 0 | AV7: 0 | AW7: 0 | AX7: 0 | AY7: 0 | AZ7: 0 | BA7: 0 | BB7: 0 | BC7: 0 | BD7: 0 | BE7: 0 | BF7: 0 | BG7: 0 | BH7: 0 | BI7: 0 | BJ7: 0 | BK7: 0 | BL7: 0 | BM7: 0 | BN7: 0 | BO7: 0 | BP7: 0 | BQ7: 0 | BR7: 0 | BS7: 0 | BT7: 0 | BU7: 0 | BV7: 0 | BW7: 0 | BX7: 0 | BY7: 0 | BZ7: 0 | CA7: 0 | CB7: 0
A8: ant(6)-Ia | B8: 0.040339008 | C8: 0.065516363 | D8: 1.452643 | E8: 0.26017218 | F8: 0.13368298 | G8: 0.40090538 | H8: 0.14665562 | I8: 0.48221802 | J8: 0.28047658 | K8: 0 | L8: 1.2072984 | M8: 0.49000731 | N8: 0.17669685 | O8: 0.92856995 | P8: 0.74953409 | Q8: 0.82231173 | R8: 0.076175735 | S8: 0.39700032 | T8: 0.54078877 | U8: 0.49048976 | V8: 1.111886 | W8: 0 | X8: 0.92531053 | Y8: 0.91160235 | Z8: 0.69807007 | AA8: 4.2587123 | AB8: 0 | AC8: 1.9235605 | AD8: 0.18569271 | AE8: 0 | AF8: 2.0705362 | AG8: 0.19456064 | AH8: 0.21493506 | AI8: 0.061670137 | AJ8: 0 | AK8: 0.42261172 | AL8: 7.2332479 | AM8: 1.845355 | AN8: 1.4161086 | AO8: 0.083205724 | AP8: 0.20864828 | AQ8: 1.2909706 | AR8: 0.56474193 | AS8: 0.58226298 | AT8: 0.77126487 | AU8: 2.8842188 | AV8: 1.0896261 | AW8: 0.27403898 | AX8: 0.20605981 | AY8: 9.7119603 | AZ8: 0 | BA8: 1.8710747 | BB8: 0.9107524 | BC8: 3.2964305 | BD8: 0.13591114 | BE8: 2.4925289 | BF8: 0.85850603 | BG8: 0.41656203 | BH8: 1.1145822 | BI8: 0.78335769 | BJ8: 0.52320931 | BK8: 26.869705 | BL8: 0.0593346 | BM8: 0.66183907 | BN8: 0.35265865 | BO8: 1.3419738 | BP8: 1.074745 | BQ8: 1.0429924 | BR8: 1.2727069 | BS8: 1.063994 | BT8: 0.47818728 | BU8: 1.5202795 | BV8: 0.87450949 | BW8: 0.31645029 | BX8: 0.0978509 | BY8: 0.19271386 | BZ8: 2.8096377 | CA8: 0.56948035 | CB8: 0.2237461
A9: ant(6)-Ib | B9: 0.085473562 | C9: 0.069410692 | D9: 0.13382513 | E9: 0.33076435 | F9: 0.1888389 | G9: 0 | H9: 0.31074583 | I9: 0 | J9: 0.79239537 | K9: 0.5792899 | L9: 0.79509193 | M9: 1.4276174 | N9: 0 | O9: 1.9675293 | P9: 1.3896519 | Q9: 0 | R9: 0.24211099 | S9: 1.4720938 | T9: 0.3819557 | U9: 0.69285967 | V9: 0.52354539 | W9: 0 | X9: 0 | Y9: 0.50830974 | Z9: 0.47063147 | AA9: 0.57598117 | AB9: 0 | AC9: 0.81515919 | AD9: 0 | AE9: 3.3981211 | AF9: 2.0423266 | AG9: 0.10306272 | AH9: 0.15180728 | AI9: 0 | AJ9: 0 | AK9: 0.74622 | AL9: 0.091228526 | AM9: 0.78201759 | AN9: 1.1252122 | AO9: 0.044075759 | AP9: 0.36841741 | AQ9: 0.58615998 | AR9: 0.079774734 | AS9: 0.51406085 | AT9: 1.5174887 | AU9: 0.27778713 | AV9: 0.25653202 | AW9: 1.016148 | AX9: 0 | AY9: 3.0447765 | AZ9: 0.047364391 | BA9: 2.2025471 | BB9: 0.72366603 | BC9: 15.184227 | BD9: 0 | BE9: 0 | BF9: 1.0611255 | BG9: 0.44132271 | BH9: 1.2546357 | BI9: 0.58094463 | BJ9: 0.49271926 | BK9: 1.5349775 | BL9: 0 | BM9: 0.23372639 | BN9: 2.6153461 | BO9: 1.8660357 | BP9: 0.43793403 | BQ9: 0.40181399 | BR9: 0.16180287 | BS9: 0.17798501 | BT9: 0.12665275 | BU9: 0.51247818 | BV9: 0.19853375 | BW9: 0.67052055 | BX9: 0 | BY9: 0.27222517 | BZ9: 0.17509671 | CA9: 0.68952066 | CB9: 0.28445484
A10: aph(2'')-Ib | B10: 0.16296959 | C10: 0 | D10: 0 | E10: 0.5255478 | F10: 0.49507264 | G10: 0.080982886 | H10: 0 | I10: 0 | J10: 0.28328134 | K10: 0 | L10: 0.032955984 | M10: 0 | N10: 0.17846382 | O10: 0.23446391 | P10: 0 | Q10: 0 | R10: 0.076937493 | S10: 0 | T10: 0 | U10: 0 | V10: 0.24955663 | W10: 0.053627725 | X10: 0.70092272 | Y10: 0.14537659 | Z10: 0 | AA10: 0.27455103 | AB10: 0 | AC10: 0 | AD10: 0.37509928 | AE10: 0 | AF10: 0.21633533 | AG10: 0 | AH10: 0.14472294 | AI10: 0 | AJ10: 0.24136314 | AK10: 0 | AL10: 0 | AM10: 0 | AN10: 0 | AO10: 0 | AP10: 0 | AQ10: 0.55880585 | AR10: 0.15210383 | AS10: 0.73510701 | AT10: 0.16692375 | AU10: 0 | AV10: 0 | AW10: 0 | AX10: 0 | AY10: 0 | AZ10: 0 | BA10: 0.41995232 | BB10: 0.22996498 | BC10: 0 | BD10: 0 | BE10: 0 | BF10: 3.6851371 | BG10: 0.31554574 | BH10: 0.98501205 | BI10: 0.079119126 | BJ10: 0 | BK10: 0 | BL10: 0 | BM10: 0 | BN10: 0 | BO10: 0.084712095 | BP10: 0 | BQ10: 0 | BR10: 0.15425207 | BS10: 0.22623873 | BT10: 0.24148458 | BU10: 0.20938394 | BV10: 0.063089613 | BW10: 0 | BX10: 0 | BY10: 0.77856398 | BZ10: 0 | CA10: 0 | CB10: 0.045196713
A11: aph(2'')-Ic | B11: 0.23888051 | C11: 0.064662729 | D11: 0 | E11: 0 | F11: 0 | G11: 0 | H11: 0 | I11: 0 | J11: 0 | K11: 0 | L11: 0 | M11: 0 | N11: 0 | O11: 0 | P11: 0 | Q11: 0 | R11: 0 | S11: 0.097956919 | T11: 0 | U11: 0 | V11: 0.12193321 | W11: 0 | X11: 0 | Y11: 1.515326 | Z11: 0 | AA11: 0 | AB11: 0 | AC11: 0 | AD11: 0 | AE11: 0 | AF11: 0 | AG11: 0.096012824 | AH11: 0 | AI11: 0 | AJ11: 0 | AK11: 0 | AL11: 0 | AM11: 0 | AN11: 0 | AO11: 0 | AP11: 0 | AQ11: 0 | AR11: 0.037158915 | AS11: 0 | AT11: 0.054372558 | AU11: 0 | AV11: 0 | AW11: 0 | AX11: 0 | AY11: 0 | AZ11: 0 | BA11: 0 | BB11: 0.11236074 | BC11: 0 | BD11: 0 | BE11: 0 | BF11: 0 | BG11: 0 | BH11: 0.068753749 | BI11: 0 | BJ11: 0 | BK11: 0 | BL11: 0 | BM11: 0 | BN11: 0 | BO11: 0.99336658 | BP11: 0.081595526 | BQ11: 0 | BR11: 0 | BS11: 0 | BT11: 0 | BU11: 0.068203239 | BV11: 0 | BW11: 2.6547809 | BX11: 0 | BY11: 0 | BZ11: 0 | CA11: 0 | CB11: 0
A12: aph(2'')-Id_aph(2'')-Ie | B12: 0 | C12: 0.98599956 | D12: 0.50694022 | E12: 0 | F12: 0 | G12: 1.2871452 | H12: 0 | I12: 0 | J12: 0 | K12: 0 | L12: 0 | M12: 0 | N12: 0 | O12: 2.0962005 | P12: 0 | Q12: 0 | R12: 0 | S12: 0 | T12: 0 | U12: 0 | V12: 0.24790394 | W12: 0 | X12: 0.46418723 | Y12: 0 | Z12: 0 | AA12: 0 | AB12: 0 | AC12: 0 | AD12: 0 | AE12: 0 | AF12: 0 | AG12: 0 | AH12: 0.57505805 | AI12: 0 | AJ12: 0 | AK12: 0.070668516 | AL12: 0.69116181 | AM12: 0 | AN12: 0 | AO12: 0.04174062 | AP12: 0 | AQ12: 0 | AR12: 0.037774129 | AS12: 0 | AT12: 0.11054553 | AU12: 0 | AV12: 0 | AW12: 0 | AX12: 0 | AY12: 0.29828936 | AZ12: 0 | BA12: 0 | BB12: 0 | BC12: 0 | BD12: 0 | BE12: 0 | BF12: 0 | BG12: 0 | BH12: 0.69892057 | BI12: 0 | BJ12: 0 | BK12: 0.66075191 | BL12: 0 | BM12: 0 | BN12: 0 | BO12: 0.084151087 | BP12: 0 | BQ12: 0.38052583 | BR12: 0.15323054 | BS12: 0.056185115 | BT12: 0.23988534 | BU12: 0.55465945 | BV12: 0.062671801 | BW12: 0 | BX12: 0 | BY12: 0 | BZ12: 0.16582007 | CA12: 0.08162372 | CB12: 0
A13: aph(3'')-Ic | B13: 0 | C13: 0 | D13: 0 | E13: 0 | F13: 0 | G13: 0 | H13: 0 | I13: 0 | J13: 0 | K13: 0 | L13: 0 | M13: 0 | N13: 0 | O13: 0 | P13: 0 | Q13: 0 | R13: 0 | S13: 0 | T13: 0 | U13: 0 | V13: 0 | W13: 0 | X13: 0 | Y13: 0 | Z13: 0 | AA13: 0 | AB13: 0 | AC13: 0 | AD13: 0 | AE13: 0 | AF13: 0 | AG13: 0 | AH13: 0 | AI13: 0 | AJ13: 0 | AK13: 0 | AL13: 0 | AM13: 0 | AN13: 0 | AO13: 0 | AP13: 0 | AQ13: 0 | AR13: 0 | AS13: 0 | AT13: 0 | AU13: 0 | AV13: 0 | AW13: 0 | AX13: 0 | AY13: 0 | AZ13: 0 | BA13: 0 | BB13: 0 | BC13: 0 | BD13: 0.037850253 | BE13: 0 | BF13: 0 | BG13: 0 | BH13: 0 | BI13: 0 | BJ13: 0 | BK13: 0 | BL13: 0 | BM13: 0 | BN13: 0 | BO13: 0 | BP13: 0 | BQ13: 0 | BR13: 0 | BS13: 0 | BT13: 0 | BU13: 0.076979391 | BV13: 0 | BW13: 0 | BX13: 0 | BY13: 0 | BZ13: 0 | CA13: 0 | CB13: 0
A14: aph(3')-Ia_aph(3')-Ic | B14: 0.94366583 | C14: 0.87579961 | D14: 0.49249615 | E14: 0.57964831 | F14: 0.39711709 | G14: 2.8582195 | H14: 0.16337005 | I14: 1.0743534 | J14: 0.31244266 | K14: 0.30455315 | L14: 0.2907881 | M14: 0 | N14: 1.6730983 | O14: 1.0343996 | P14: 1.2524384 | Q14: 0 | R14: 0.16971506 | S14: 1.5478634 | T14: 0.30121139 | U14: 0.12142026 | V14: 0.27524629 | W14: 0.82807516 | X14: 1.5461531 | Y14: 1.3361819 | Z14: 0.84832312 | AA14: 2.1196954 | AB14: 0.68176842 | AC14: 0 | AD14: 0.10342811 | AE14: 0 | AF14: 0.79535049 | AG14: 0.48765337 | AH14: 1.9154507 | AI14: 0.34349359 | AJ14: 1.3310467 | AK14: 0.94155406 | AL14: 0.95924112 | AM14: 4.3169096 | AN14: 94.650202 | AO14: 0.092688729 | AP14: 0.38738008 | AQ14: 0.61632998 | AR14: 0.16776157 | AS14: 0.48646788 | AT14: 5.0322602 | AU14: 1.6794887 | AV14: 1.6184153 | AW14: 0.30527136 | AX14: 0.30605943 | AY14: 1.1039631 | AZ14: 0.099604529 | BA14: 1.1579568 | BB14: 2.9168353 | BC14: 0.63863072 | BD14: 0.34065227 | BE14: 2.9501416 | BF14: 0.23908762 | BG14: 1.508123 | BH14: 0.3880037 | BI14: 0.26179123 | BJ14: 0 | BK14: 0 | BL14: 0.925358 | BM14: 2.2732469 | BN14: 0.19642568 | BO14: 0.37372983 | BP14: 1.0130445 | BQ14: 2.112478 | BR14: 1.1342064 | BS14: 6.6124923 | BT14: 0.93220149 | BU14: 1.8475054 | BV14: 0.13916826 | BW14: 1.2338071 | BX14: 2.5070696 | BY14: 1.144947 | BZ14: 0.36821809 | CA14: 2.4469111 | CB14: 1.1216096
A15: aph(3')-Ib | B15: 0.1348094 | C15: 0.2189499 | D15: 0.21106978 | E15: 0 | F15: 0 | G15: 0 | H15: 0.16337005 | I15: 0 | J15: 0 | K15: 0 | L15: 0 | M15: 0 | N15: 0 | O15: 0.2585999 | P15: 11.793795 | Q15: 0 | R15: 0 | S15: 0 | T15: 0.20080759 | U15: 0.12142026 | V15: 0 | W15: 0 | X15: 0.25769218 | Y15: 0 | Z15: 0.070693593 | AA15: 0.10093788 | AB15: 0.51132631 | AC15: 0.42855796 | AD15: 0 | AE15: 0 | AF15: 0.23860515 | AG15: 0 | AH15: 0.15962089 | AI15: 0.068698718 | AJ15: 0 | AK15: 0.15692568 | AL15: 0 | AM15: 0.34261187 | AN15: 5.1268859 | AO15: 0.13903309 | AP15: 0 | AQ15: 0 | AR15: 0.083880786 | AS15: 0.16215596 | AT15: 0.061369027 | AU15: 0.1460425 | AV15: 4.8552458 | AW15: 0 | AX15: 0.076514858 | AY15: 0.99356676 | AZ15: 0 | BA15: 0 | BB15: 0.25363785 | BC15: 0 | BD15: 0.18925126 | BE15: 0.52061322 | BF15: 0 | BG15: 0.11600946 | BH15: 0 | BI15: 0 | BJ15: 0 | BK15: 0.44017737 | BL15: 0.198291 | BM15: 6.451106 | BN15: 0.19642568 | BO15: 0.37372983 | BP15: 0.092094951 | BQ15: 0.1056239 | BR15: 0 | BS15: 0 | BT15: 0.13317164 | BU15: 0.076979391 | BV15: 0 | BW15: 0 | BX15: 0.10900302 | BY15: 0.07155919 | BZ15: 0 | CA15: 0.090626337 | CB15: 0.024924658
A16: aph(3')-Id | B16: 0 | C16: 0 | D16: 0 | E16: 0 | F16: 0 | G16: 0 | H16: 0 | I16: 0 | J16: 0 | K16: 0 | L16: 0 | M16: 0 | N16: 0 | O16: 0 | P16: 0 | Q16: 0 | R16: 0 | S16: 0 | T16: 0 | U16: 0 | V16: 0 | W16: 0 | X16: 0 | Y16: 0 | Z16: 0 | AA16: 0 | AB16: 0 | AC16: 0 | AD16: 0 | AE16: 0 | AF16: 0 | AG16: 0 | AH16: 0 | AI16: 0 | AJ16: 0 | AK16: 0 | AL16: 0 | AM16: 0 | AN16: 0 | AO16: 0 | AP16: 0 | AQ16: 0.20544333 | AR16: 0 | AS16: 0 | AT16: 0 | AU16: 0 | AV16: 0 | AW16: 0 | AX16: 0 | AY16: 0 | AZ16: 0 | BA16: 0 | BB16: 0 | BC16: 0 | BD16: 0 | BE16: 0 | BF16: 0 | BG16: 0 | BH16: 0 | BI16: 0 | BJ16: 0 | BK16: 0 | BL16: 0 | BM16: 0 | BN16: 0 | BO16: 0 | BP16: 0 | BQ16: 0 | BR16: 0 | BS16: 0 | BT16: 0 | BU16: 0 | BV16: 0 | BW16: 0 | BX16: 0 | BY16: 0 | BZ16: 0 | CA16: 0 | CB16: 0
... A412: aadK | B412: 0 | C412: 0 | D412: 0 | E412: 0 | F412: 0 | G412: 0 | H412: 0 | I412: 0 | J412: 0 | K412: 0 | L412: 0 | M412: 0 | N412: 0 | O412: 0 | P412: 0 | Q412: 0 | R412: 0 | S412: 0 | T412: 0 | U412: 0 | V412: 0 | W412: 0 | X412: 0 | Y412: 0 | Z412: 0 | AA412: 0 | AB412: 0 | AC412: 0 | AD412: 0 | AE412: 0 | AF412: 0 | AG412: 0 | AH412: 0 | AI412: 0 | AJ412: 0 | AK412: 0 | AL412: 0 | AM412: 0 | AN412: 0.18819338 | AO412: 0 | AP412: 0 | AQ412: 0 | AR412: 0 | AS412: 0 | AT412: 0 | AU412: 0 | AV412: 0 | AW412: 0 | AX412: 0 | AY412: 0 | AZ412: 0 | BA412: 0 | BB412: 0 | BC412: 0 | BD412: 0.03612375 | BE412: 0 | BF412: 0 | BG412: 0 | BH412: 0 | BI412: 0 | BJ412: 0 | BK412: 0 | BL412: 0 | BM412: 0 | BN412: 0 | BO412: 0 | BP412: 0 | BQ412: 0 | BR412: 0 | BS412: 0 | BT412: 0 | BU412: 0 | BV412: 0 | BW412: 0 | BX412: 0 | BY412: 0.068295086 | BZ412: 0 | CA412: 0 | CB412: 0
A413: Sum | B413: =SUM(B5:B412) -> 1188.716 | C413: =SUM(C5:C412) -> 719.83369 | D413: =SUM(D5:D412) -> 832.29468 | E413: =SUM(E5:E412) -> 574.57725 | F413: =SUM(F5:F412) -> 640.39453 | G413: =SUM(G5:G412) -> 1716.6914 | H413: =SUM(H5:H412) -> 4616.8552 | I413: =SUM(I5:I412) -> 2344.6786 | ... CB413: =SUM(CB5:CB412) -> 1046.1921

Sheet AMR by Region
A1: Site | B1: Country | C1: Region | D1: AMR (FPKM)
A2: ALB.17 | B2: =HLOOKUP($A2,GS.ResFind.Gene.FPKM!$A$1:$CB$413,3) -> Albania | C2: =HLOOKUP($A2,GS.ResFind.Gene.FPKM!$A$1:$CB$413,4) -> Europe | D2: =HLOOKUP($A2,GS.ResFind.Gene.FPKM!$A$1:$CB$413,413) -> 1188.716
A3: AUS.18 | B3: =HLOOKUP($A3,GS.ResFind.Gene.FPKM!$A$1:$CB$413,3) -> Australia | C3: =HLOOKUP($A3,GS.ResFind.Gene.FPKM!$A$1:$CB$413,4) -> Oceania | D3: =HLOOKUP($A3,GS.ResFind.Gene.FPKM!$A$1:$CB$413,413) -> 719.83369
A4: AUS.18a | B4: =HLOOKUP($A4,GS.ResFind.Gene.FPKM!$A$1:$CB$413,3) -> Australia | C4: =HLOOKUP($A4,GS.ResFind.Gene.FPKM!$A$1:$CB$413,4) -> Oceania | D4: =HLOOKUP($A4,GS.ResFind.Gene.FPKM!$A$1:$CB$413,413) -> 832.29468
A5: AUT.70 | B5: =HLOOKUP($A5,GS.ResFind.Gene.FPKM!$A$1:$CB$413,3) -> Austria | C5: =HLOOKUP($A5,GS.ResFind.Gene.FPKM!$A$1:$CB$413,4) -> Europe | D5: =HLOOKUP($A5,GS.ResFind.Gene.FPKM!$A$1:$CB$413,413) -> 574.57725
A6: BGR.66 | B6: =HLOOKUP($A6,GS.ResFind.Gene.FPKM!$A$1:$CB$413,3) -> Bulgaria | C6: =HLOOKUP($A6,GS.ResFind.Gene.FPKM!$A$1:$CB$413,4) -> Europe | D6: =HLOOKUP($A6,GS.ResFind.Gene.FPKM!$A$1:$CB$413,413) -> 640.39453
A7: BRA.53 | B7: =HLOOKUP($A7,GS.ResFind.Gene.FPKM!$A$1:$CB$413,3) -> Brasil | C7: =HLOOKUP($A7,GS.ResFind.Gene.FPKM!$A$1:$CB$413,4) -> South America | D7: =HLOOKUP($A7,GS.ResFind.Gene.FPKM!$A$1:$CB$413,413) -> 1716.6914
A8: BRA.53a | B8: =HLOOKUP($A8,GS.ResFind.Gene.FPKM!$A$1:$CB$413,3) -> Brasil | C8: =HLOOKUP($A8,GS.ResFind.Gene.FPKM!$A$1:$CB$413,4) -> South America | D8: =HLOOKUP($A8,GS.ResFind.Gene.FPKM!$A$1:$CB$413,413) -> 4616.8552
A9: BWA.19 | B9: =HLOOKUP($A9,GS.ResFind.Gene.FPKM!$A$1:$CB$413,3) -> Botswana | C9: =HLOOKUP($A9,GS.ResFind.Gene.FPKM!$A$1:$CB$413,4) -> Africa | D9: =HLOOKUP($A9,GS.ResFind.Gene.FPKM!$A$1:$CB$413,413) -> 2344.6786
A10: CAN.22 | B10: =HLOOKUP($A10,GS.ResFind.Gene.FPKM!$A$1:$CB$413,3) -> Canada | C10: =HLOOKUP($A10,GS.ResFind.Gene.FPKM!$A$1:$CB$413,4) -> North America | D10: =HLOOKUP($A10,GS.ResFind.Gene.FPKM!$A$1:$CB$413,413) -> 1005.4167
A11: CAN.22a | B11: =HLOOKUP($A11,GS.ResFind.Gene.FPKM!$A$1:$CB$413,3) -> Canada | C11: =HLOOKUP($A11,GS.ResFind.Gene.FPKM!$A$1:$CB$413,4) -> North America | D11: =HLOOKUP($A11,GS.ResFind.Gene.FPKM!$A$1:$CB$413,413) -> 690.33264
A12: CAN.22b | B12: =HLOOKUP($A12,GS.ResFind.Gene.FPKM!$A$1:$CB$413,3) -> Canada | C12: =HLOOKUP($A12,GS.ResFind.Gene.FPKM!$A$1:$CB$413,4) -> North America | D12: =HLOOKUP($A12,GS.ResFind.Gene.FPKM!$A$1:$CB$413,413) -> 990.66017
A13: CAN.22c | B13: =HLOOKUP($A13,GS.ResFind.Gene.FPKM!$A$1:$CB$413,3) -> Canada | C13: =HLOOKUP($A13,GS.ResFind.Gene.FPKM!$A$1:$CB$413,4) -> North America | D13: =HLOOKUP($A13,GS.ResFind.Gene.FPKM!$A$1:$CB$413,413) -> 651.28132
... A80: ZMB.49b | B80: =HLOOKUP($A80,GS.ResFind.Gene.FPKM!$A$1:$CB$413,3) -> Zambia | C80: =HLOOKUP($A80,GS.ResFind.Gene.FPKM!$A$1:$CB$413,4) -> Africa | D80: =HLOOKUP($A80,GS.ResFind.Gene.FPKM!$A$1:$CB$413,413) -> 1046.1921

Sheet GS.Bacteria.Genus.count
B1: ALB.17 | C1: AUS.18 | D1: AUS.18a | E1: AUT.70 | F1: BGR.66 | G1: BRA.53 | H1: BRA.53a | I1: BWA.19 | J1: CAN.22 | K1: CAN.22a | L1: CAN.22b | M1: CAN.22c | N1: CHE.67 | O1: CHN.64 | P1: CIV.13 | Q1: COL.2 | R1: CZE.23 | S1: DEU.27 | T1: DNK.71_RA | U1: DNK.71_RD | V1: DNK.71_RL | W1: ECU.14 | X1: ECU.14a | Y1: ESP.75 | Z1: ETH.24 | AA1: FIN.25 | AB1: GEO.59 | AC1: GHA.4 | AD1: HRV.68 | AE1: HUN.61 | AF1: IND.11 | AG1: IRL.69 | AH1: IRN.12 | AI1: ISL.28 | AJ1: ISR.29 | AK1: ITA.30 | AL1: KAZ.6 | AM1: KEN.72 | AN1: KHM.21 | AO1: LKA.40 | AP1: LUX.32 | AQ1: LVA.31 | AR1: MDA.65 | AS1: MKD.62 | AT1: MLT.63 | AU1: MYS.54 | AV1: NGA.50 | AW1: NLD.43 | AX1: NOR.34 | AY1: NPL.33 | AZ1: NZL.56 | BA1: PAK.7 | BB1: PER.35 | BC1: POL.36 | BD1: SEN.8 | BE1: SGP.52 | BF1: SRB.37 | BG1: SVK.9 | BH1: SVN.38 | BI1: SWE.41 | BJ1: SWE.41a | BK1: TGO.44 | BL1: TUR.46 | BM1: TZA.15 | BN1: USA.74 | BO1: USA.74a | BP1: USA.74b | BQ1: USA.74c | BR1: USA.74d | BS1: USA.74e | BT1: USA.74f | BU1: USA.74g | BV1: USA.74h | BW1: USA.74i | BX1: VNM.48 | BY1: XK.60 | BZ1: ZAF.39 | CA1: ZMB.49 | CB1: ZMB.49b
A2: Abiotrophia | B2: 141 | C2: 21 | D2: 61 | E2: 232 | F2: 25 | G2: 18 | H2: 7 | I2: 33 | J2: 490 | K2: 83 | L2: 660 | M2: 246 | N2: 129 | O2: 21 | P2: 38 | Q2: 28 | R2: 84 | S2: 223 | T2: 146 | U2: 260 | V2: 153 | W2: 6 | X2: 61 | Y2: 167 | Z2: 74 | AA2: 128 | AB2: 44 | AC2: 2 | AD2: 120 | AE2: 5 | AF2: 16 | AG2: 115 | AH2: 30 | AI2: 51 | AJ2: 48 | AK2: 34 | AL2: 67 | AM2: 68 | AN2: 23 | AO2: 18 | AP2: 102 | AQ2: 87 | AR2: 127 | AS2: 159 | AT2: 26 | AU2: 50 | AV2: 331 | AW2: 46 | AX2: 18 | AY2: 525 | AZ2: 118 | BA2: 44 | BB2: 160 | BC2: 143 | BD2: 59 | BE2: 19 | BF2: 178 | BG2: 53 | BH2: 414 | BI2: 198 | BJ2: 84 | BK2: 3 | BL2: 8 | BM2: 14 | BN2: 39 | BO2: 72 | BP2: 61 | BQ2: 39 | BR2: 148 | BS2: 51 | BT2: 35 | BU2: 71 | BV2: 152 | BW2: 62 | BX2: 5 | BY2: 303 | BZ2: 25 | CA2: 89 | CB2: 193
A3: Acaricomes | B3: 17 | C3: 0 | D3: 1 | E3: 1 | F3: 0 | G3: 0 | H3: 0 | I3: 0 | J3: 0 | K3: 0 | L3: 0 | M3: 2 | N3: 0 | O3: 0 | P3: 0 | Q3: 0 | R3: 0 | S3: 0 | T3: 1 | U3: 2 | V3: 0 | W3: 0 | X3: 0 | Y3: 3 | Z3: 0 | AA3: 0 | AB3: 0 | AC3: 1 | AD3: 0 | AE3: 0 | AF3: 0 | AG3: 0 | AH3: 0 | AI3: 0 | AJ3: 0 | AK3: 0 | AL3: 0 | AM3: 0 | AN3: 0 | AO3: 0 | AP3: 0 | AQ3: 0 | AR3: 0 | AS3: 0 | AT3: 0 | AU3: 0 | AV3: 0 | AW3: 0 | AX3: 0 | AY3: 5 | AZ3: 0 | BA3: 0 | BB3: 0 | BC3: 0 | BD3: 0 | BE3: 0 | BF3: 1 | BG3: 0 | BH3: 0 | BI3: 1 | BJ3: 1 | BK3: 0 | BL3: 0 | BM3: 0 | BN3: 0 | BO3: 0 | BP3: 0 | BQ3: 0 | BR3: 0 | BS3: 1 | BT3: 0 | BU3: 0 | BV3: 1 | BW3: 0 | BX3: 0 | BY3: 2 | BZ3: 0 | CA3: 0 | CB3: 0
A4: Acaryochloris | B4: 0 | C4: 0 | D4: 0 | E4: 0 | F4: 0 | G4: 0 | H4: 0 | I4: 0 | J4: 0 | K4: 0 | L4: 0 | M4: 0 | N4: 0 | O4: 0 | P4: 0 | Q4: 0 | R4: 0 | S4: 0 | T4: 0 | U4: 0 | V4: 0 | W4: 0 | X4: 0 | Y4: 0 | Z4: 0 | AA4: 0 | AB4: 0 | AC4: 0 | AD4: 0 | AE4: 0 | AF4: 0 | AG4: 0 | AH4: 0 | AI4: 0 | AJ4: 0 | AK4: 0 | AL4: 0 | AM4: 0 | AN4: 0 | AO4: 0 | AP4: 0 | AQ4: 0 | AR4: 0 | AS4: 0 | AT4: 0 | AU4: 0 | AV4: 0 | AW4: 0 | AX4: 0 | AY4: 0 | AZ4: 0 | BA4: 0 | BB4: 0 | BC4: 0 | BD4: 0 | BE4: 0 | BF4: 0 | BG4: 0 | BH4: 0 | BI4: 0 | BJ4: 0 | BK4: 0 | BL4: 0 | BM4: 0 | BN4: 0 | BO4: 0 | BP4: 0 | BQ4: 0 | BR4: 0 | BS4: 0 | BT4: 0 | BU4: 0 | BV4: 0 | BW4: 0 | BX4: 0 | BY4: 0 | BZ4: 0 | CA4: 0 | CB4: 0
A5: Acetivibrio | B5: 570 | C5: 145 | D5: 705 | E5: 1037 | F5: 340 | G5: 346 | H5: 544 | I5: 359 | J5: 473 | K5: 151 | L5: 1181 | M5: 389 | N5: 473 | O5: 151 | P5: 430 | Q5: 439 | R5: 417 | S5: 453 | T5: 442 | U5: 898 | V5: 515 | W5: 44 | X5: 368 | Y5: 933 | Z5: 588 | AA5: 774 | AB5: 28 | AC5: 38 | AD5: 299 | AE5: 78 | AF5: 1277 | AG5: 558 | AH5: 295 | AI5: 201 | AJ5: 290 | AK5: 303 | AL5: 264 | AM5: 1140 | AN5: 266 | AO5: 69 | AP5: 609 | AQ5: 434 | AR5: 407 | AS5: 1067 | AT5: 654 | AU5: 1004 | AV5: 971 | AW5: 1838 | AX5: 533 | AY5: 1915 | AZ5: 71 | BA5: 975 | BB5: 793 | BC5: 882 | BD5: 228 | BE5: 133 | BF5: 590 | BG5: 381 | BH5: 1368 | BI5: 959 | BJ5: 753 | BK5: 534 | BL5: 25 | BM5: 1166 | BN5: 683 | BO5: 776 | BP5: 953 | BQ5: 934 | BR5: 1493 | BS5: 1077 | BT5: 453 | BU5: 1388 | BV5: 1037 | BW5: 341 | BX5: 9 | BY5: 825 | BZ5: 579 | CA5: 1221 | CB5: 3041
A6: Acetobacter | B6: 69 | C6: 132 | D6: 1243 | E6: 268 | F6: 244 | G6: 122 | H6: 355 | I6: 162 | J6: 197 | K6: 27 | L6: 467 | M6: 192 | N6: 98 | O6: 161 | P6: 3292 | Q6: 25 | R6: 155 | S6: 97 | T6: 449 | U6: 259 | V6: 143 | W6: 12 | X6: 93 | Y6: 307 | Z6: 2137 | AA6: 370 | AB6: 9 | AC6: 1019 | AD6: 36 | AE6: 3 | AF6: 3327 | AG6: 141 | AH6: 57 | AI6: 130 | AJ6: 144 | AK6: 91 | AL6: 102 | AM6: 437 | AN6: 52 | AO6: 1342 | AP6: 152 | AQ6: 132 | AR6: 43 | AS6: 48 | AT6: 208 | AU6: 185 | AV6: 800 | AW6: 64 | AX6: 176 | AY6: 43 | AZ6: 150 | BA6: 570 | BB6: 167 | BC6: 190 | BD6: 61 | BE6: 103 | BF6: 76 | BG6: 222 | BH6: 230 | BI6: 354 | BJ6: 528 | BK6: 81 | BL6: 9 | BM6: 2945 | BN6: 773 | BO6: 64 | BP6: 477 | BQ6: 88 | BR6: 491 | BS6: 178 | BT6: 155 | BU6: 150 | BV6: 257 | BW6: 96 | BX6: 189 | BY6: 20 | BZ6: 43 | CA6: 764 | CB6: 432
A7: Acetobacterium | B7: 3633 | C7: 1424 | D7: 11939 | E7: 2032 | F7: 1867 | G7: 909 | H7: 394 | I7: 449 | J7: 21589 | K7: 5003 | L7: 29679 | M7: 13735 | N7: 5629 | O7: 278 | P7: 705 | Q7: 1961 | R7: 6963 | S7: 27498 | T7: 9759 | U7: 9955 | V7: 9196 | W7: 90 | X7: 258 | Y7: 24289 | Z7: 1745 | AA7: 23629 | AB7: 133 | AC7: 246 | AD7: 8383 | AE7: 635 | AF7: 178 | AG7: 672 | AH7: 766 | AI7: 476 | AJ7: 697 | AK7: 1637 | AL7: 2016 | AM7: 6570 | AN7: 393 | AO7: 78 | AP7: 1535 | AQ7: 3195 | AR7: 3101 | AS7: 6837 | AT7: 2180 | AU7: 633 | AV7: 560 | AW7: 4720 | AX7: 983 | AY7: 30580 | AZ7: 292 | BA7: 949 | BB7: 152 | BC7: 10712 | BD7: 357 | BE7: 674 | BF7: 5660 | BG7: 3155 | BH7: 32616 | BI7: 13406 | BJ7: 2729 | BK7: 263 | BL7: 148 | BM7: 344 | BN7: 9312 | BO7: 1502 | BP7: 19515 | BQ7: 19727 | BR7: 17586 | BS7: 16559 | BT7: 17433 | BU7: 18464 | BV7: 53460 | BW7: 6473 | BX7: 110 | BY7: 4427 | BZ7: 1694 | CA7: 933 | CB7: 1478
A8: Acetohalobium | B8: 0 | C8: 0 | D8: 0 | E8: 0 | F8: 0 | G8: 0 | H8: 0 | I8: 0 | J8: 0 | K8: 0 | L8: 0 | M8: 0 | N8: 0 | O8: 0 | P8: 0 | Q8: 0 | R8: 0 | S8: 0 | T8: 0 | U8: 0 | V8: 0 | W8: 0 | X8: 0 | Y8: 0 | Z8: 0 | AA8: 0 | AB8: 0 | AC8: 0 | AD8: 0 | AE8: 0 | AF8: 2 | AG8: 0 | AH8: 0 | AI8: 0 | AJ8: 0 | AK8: 0 | AL8: 0 | AM8: 5 | AN8: 0 | AO8: 0 | AP8: 0 | AQ8: 0 | AR8: 0 | AS8: 0 | AT8: 1 | AU8: 0 | AV8: 0 | AW8: 1 | AX8: 0 | AY8: 0 | AZ8: 0 | BA8: 0 | BB8: 0 | BC8: 0 | BD8: 0 | BE8: 0 | BF8: 0 | BG8: 0 | BH8: 0 | BI8: 0 | BJ8: 0 | BK8: 0 | BL8: 0 | BM8: 0 | BN8: 0 | BO8: 0 | BP8: 0 | BQ8: 1 | BR8: 0 | BS8: 0 | BT8: 1 | BU8: 0 | BV8: 0 | BW8: 0 | BX8: 0 | BY8: 0 | BZ8: 0 | CA8: 0 | CB8: 0
A9: Acetonema | B9: 19 | C9: 4 | D9: 12 | E9: 9 | F9: 14 | G9: 7 | H9: 748 | I9: 43 | J9: 32 | K9: 2 | L9: 25 | M9: 10 | N9: 2 | O9: 13 | P9: 32 | Q9: 164 | R9: 5 | S9: 35 | T9: 5 | U9: 17 | V9: 4 | W9: 1 | X9: 91 | Y9: 25 | Z9: 11 | AA9: 9 | AB9: 0 | AC9: 26 | AD9: 13 | AE9: 0 | AF9: 105 | AG9: 9 | AH9: 16 | AI9: 4 | AJ9: 11 | AK9: 15 | AL9: 4 | AM9: 26 | AN9: 318 | AO9: 13 | AP9: 13 | AQ9: 20 | AR9: 10 | AS9: 11 | AT9: 14 | AU9: 95 | AV9: 89 | AW9: 26 | AX9: 3 | AY9: 7 | AZ9: 0 | BA9: 55 | BB9: 5 | BC9: 17 | BD9: 14 | BE9: 25 | BF9: 1 | BG9: 8 | BH9: 13 | BI9: 11 | BJ9: 6 | BK9: 10 | BL9: 0 | BM9: 7 | BN9: 14 | BO9: 2 | BP9: 41 | BQ9: 34 | BR9: 14 | BS9: 26 | BT9: 36 | BU9: 33 | BV9: 45 | BW9: 6 | BX9: 22 | BY9: 6 | BZ9: 8 | CA9: 33 | CB9: 235
A10: Acholeplasma | B10: 142 | C10: 80 | D10: 294 | E10: 155 | F10: 170 | G10: 156 | H10: 271 | I10: 28 | J10: 237 | K10: 120 | L10: 453 | M10: 50 | N10: 176 | O10: 177 | P10: 96 | Q10: 16 | R10: 232 | S10: 176 | T10: 378 | U10: 307 | V10: 262 | W10: 4 | X10: 13 | Y10: 394 | Z10: 155 | AA10: 181 | AB10: 151 | AC10: 143 | AD10: 488 | AE10: 179 | AF10: 50 | AG10: 245 | AH10: 74 | AI10: 37 | AJ10: 16 | AK10: 33 | AL10: 68 | AM10: 354 | AN10: 22 | AO10: 5 | AP10: 56 | AQ10: 79 | AR10: 264 | AS10: 246 | AT10: 177 | AU10: 147 | AV10: 212 | AW10: 1936 | AX10: 50 | AY10: 256 | AZ10: 323 | BA10: 217 | BB10: 744 | BC10: 262 | BD10: 57 | BE10: 221 | BF10: 89 | BG10: 61 | BH10: 563 | BI10: 655 | BJ10: 268 | BK10: 303258 | BL10: 222 | BM10: 215 | BN10: 288 | BO10: 257 | BP10: 349 | BQ10: 225 | BR10: 576 | BS10: 310 | BT10: 115 | BU10: 304 | BV10: 742 | BW10: 187 | BX10: 231 | BY10: 200 | BZ10: 85 | CA10: 266 | CB10: 260
A11: Achromobacter | B11: 7416 | C11: 5042 | D11: 10959 | E11: 7816 | F11: 6171 | G11: 4194 | H11: 3141 | I11: 8979 | J11: 23476 | K11: 1917 | L11: 13055 | M11: 27050 | N11: 6764 | O11: 3012 | P11: 7262 | Q11: 947 | R11: 3886 | S11: 9303 | T11: 5057 | U11: 6686 | V11: 3009 | W11: 6023 | X11: 1697 | Y11: 23011 | Z11: 6513 | AA11: 5065 | AB11: 17499 | AC11: 2320 | AD11: 3768 | AE11: 311 | AF11: 5858 | AG11: 9058 | AH11: 4592 | AI11: 3783 | AJ11: 2994 | AK11: 4487 | AL11: 2338 | AM11: 7415 | AN11: 2108 | AO11: 1757 | AP11: 7630 | AQ11: 2737 | AR11: 3329 | AS11: 8538 | AT11: 7179 | AU11: 5973 | AV11: 6540 | AW11: 4821 | AX11: 4123 | AY11: 1352 | AZ11: 4546 | BA11: 4361 | BB11: 3271 | BC11: 3405 | BD11: 6358 | BE11: 4792 | BF11: 4013 | BG11: 4653 | BH11: 4138 | BI11: 7778 | BJ11: 6166 | BK11: 10158 | BL11: 118264 | BM11: 2496 | BN11: 4337 | BO11: 3541 | BP11: 5114 | BQ11: 3909 | BR11: 5844 | BS11: 6840 | BT11: 6828 | BU11: 7873 | BV11: 8590 | BW11: 8771 | BX11: 39637 | BY11: 2996 | BZ11: 3111 | CA11: 10991 | CB11: 20557
A12: Acidaminococcus | B12: 2820 | C12: 684 | D12: 3802 | E12: 4778 | F12: 3217 | G12: 1926 | H12: 2678 | I12: 1624 | J12: 1323 | K12: 505 | L12: 8372 | M12: 762 | N12: 1947 | O12: 678 | P12: 2660 | Q12: 3508 | R12: 2197 | S12: 1970 | T12: 1673 | U12: 2720 | V12: 1290 | W12: 146 | X12: 3082 | Y12: 5192 | Z12: 9547 | AA12: 1929 | AB12: 296 | AC12: 118 | AD12: 1164 | AE12: 226 | AF12: 9958 | AG12: 1531 | AH12: 3018 | AI12: 513 | AJ12: 1852 | AK12: 1602 | AL12: 887 | AM12: 4345 | AN12: 1322 | AO12: 2003 | AP12: 2213 | AQ12: 997 | AR12: 3769 | AS12: 4013 | AT12: 3083 | AU12: 19666 | AV12: 9448 | AW12: 608 | AX12: 1327 | AY12: 1117 | AZ12: 412 | BA12: 18492 | BB12: 3115 | BC12: 1399 | BD12: 1110 | BE12: 3187 | BF12: 1768 | BG12: 3177 | BH12: 2349 | BI12: 2207 | BJ12: 2595 | BK12: 126 | BL12: 110 | BM12: 8031 | BN12: 2025 | BO12: 2765 | BP12: 6121 | BQ12: 7553 | BR12: 9672 | BS12: 5221 | BT12: 1837 | BU12: 9067 | BV12: 4533 | BW12: 1537 | BX12: 267 | BY12: 4630 | BZ12: 1379 | CA12: 3107 | CB12: 9064
A13: Acidihalobacter | B13: 9 | C13: 18 | D13: 7 | E13: 11 | F13: 9 | G13: 6 | H13: 70 | I13: 40 | J13: 56 | K13: 0 | L13: 51 | M13: 73 | N13: 46 | O13: 58 | P13: 39 | Q13: 0 | R13: 4 | S13: 7 | T13: 72 | U13: 6 | V13: 4 | W13: 8 | X13: 4 | Y13: 154 | Z13: 20 | AA13: 29 | AB13: 0 | AC13: 114 | AD13: 10 | AE13: 3 | AF13: 21 | AG13: 49 | AH13: 8 | AI13: 8 | AJ13: 5 | AK13: 53 | AL13: 3 | AM13: 32 | AN13: 40 | AO13: 6 | AP13: 7 | AQ13: 4 | AR13: 2 | AS13: 6 | AT13: 12 | AU13: 53 | AV13: 33 | AW13: 113 | AX13: 37 | AY13: 5 | AZ13: 0 | BA13: 48 | BB13: 7 | BC13: 10 | BD13: 7 | BE13: 62 | BF13: 1 | BG13: 3 | BH13: 13 | BI13: 44 | BJ13: 4 | BK13: 36 | BL13: 4 | BM13: 4 | BN13: 39 | BO13: 10 | BP13: 38 | BQ13: 7 | BR13: 6 | BS13: 30 | BT13: 3 | BU13: 26 | BV13: 7 | BW13: 83 | BX13: 6 | BY13: 2 | BZ13: 4 | CA13: 25 | CB13: 117
... A1547: Zymomonas | B1547: 566 | C1547: 329 | D1547: 635 | E1547: 769 | F1547: 353 | G1547: 205 | H1547: 456 | I1547: 904 | J1547: 684 | K1547: 200 | L1547: 729 | M1547: 1215 | N1547: 863 | O1547: 134 | P1547: 367 | Q1547: 96 | R1547: 560 | S1547: 1319 | T1547: 194 | U1547: 323 | V1547: 208 | W1547: 134 | X1547: 258 | Y1547: 3231 | Z1547: 281 | AA1547: 1207 | AB1547: 27 | AC1547: 201 | AD1547: 381 | AE1547: 38 | AF1547: 401 | AG1547: 819 | AH1547: 362 | AI1547: 288 | AJ1547: 329 | AK1547: 439 | AL1547: 154 | AM1547: 364 | AN1547: 181 | AO1547: 24 | AP1547: 792 | AQ1547: 209 | AR1547: 499 | AS1547: 518 | AT1547: 343 | AU1547: 613 | AV1547: 438 | AW1547: 492 | AX1547: 396 | AY1547: 219 | AZ1547: 126 | BA1547: 197 | BB1547: 207 | BC1547: 394 | BD1547: 228 | BE1547: 392 | BF1547: 483 | BG1547: 260 | BH1547: 552 | BI1547: 523 | BJ1547: 436 | BK1547: 216 | BL1547: 300 | BM1547: 932 | BN1547: 1030 | BO1547: 636 | BP1547: 1413 | BQ1547: 304 | BR1547: 571 | BS1547: 1485 | BT1547: 819 | BU1547: 413 | BV1547: 454 | BW1547: 1262 | BX1547: 265 | BY1547: 435 | BZ1547: 372 | CA1547: 390 | CB1547: 1460

Sheet Sample count
A1: SampleSite id | B1: Country counter | C1: City counter | D1: Country Id | E1: Run Id | F1: Sample | G1: Country | H1: Region | I1: City | J1: Reads | K1: Reads per SampleSite
A2: 1 | B2: 1 | C2: 1 | D2: 17 | E2: 1 | F2: ALB.17 | G2: Albania | H2: Europe | I2: Tirana | J2: =SUM('[1]read_count_fq.txt'!B6:B7) -> 81330740
A3: 1 | D3: 17 | E3: 2 | F3: ALB.17_1 | G3: Albania | H3: Europe | I3: Tirana | J3: =SUM('[1]read_count_fq.txt'!B2:B3) -> 30557128
A4: 1 | D4: 17 | E4: 3 | F4: ALB.17_2 | G4: Albania | H4: Europe | I4: Tirana | J4: =SUM('[1]read_count_fq.txt'!B4:B5) -> 49129762 | K4: =SUM(J2:J4) -> 161017630
A5: 2 | B5: 2 | C5: 2 | D5: 18 | E5: 1 | F5: AUS.18 | G5: Australia | H5: Oceania | I5: Woden | J5: =SUM('[1]read_count_fq.txt'!B26:B27) -> 32703150
A6: 2 | D6: 18 | E6: 2 | F6: AUS.18_1 | G6: Australia | H6: Oceania | I6: Woden | J6: =SUM('[1]read_count_fq.txt'!B8:B9) -> 8765460
A7: 2 | D7: 18 | E7: 3 | F7: AUS.18_2 | G7: Australia | H7: Oceania | I7: Woden | J7: =SUM('[1]read_count_fq.txt'!B10:B11) -> 6572346
A8: 2 | D8: 18 | E8: 4 | F8: AUS.18_3 | G8: Australia | H8: Oceania | I8: Woden | J8: =SUM('[1]read_count_fq.txt'!B12:B13) -> 40391740
A9: 2 | D9: 18 | E9: 5 | F9: AUS.18_4 | G9: Australia | H9: Oceania | I9: Woden | J9: =SUM('[1]read_count_fq.txt'!B14:B15) -> 38240876 | K9: =SUM(J5:J9) -> 126673572
A10: 3 | B10: 2 | C10: 3 | D10: 18 | E10: 1 | F10: AUS.18a | G10: Australia | H10: Oceania | I10: Melbourne | J10: =SUM('[1]read_count_fq.txt'!B24:B25) -> 12628000
A11: 3 | D11: 18 | E11: 2 | F11: AUS.18a_1 | G11: Australia | H11: Oceania | I11: Melbourne | J11: =SUM('[1]read_count_fq.txt'!B16:B17) -> 7418564
A12: 3 | D12: 18 | E12: 3 | F12: AUS.18a_2 | G12: Australia | H12: Oceania | I12: Melbourne | J12: =SUM('[1]read_count_fq.txt'!B18:B19) -> 71585158
A13: 3 | D13: 18 | E13: 4 | F13: AUS.18a_3 | G13: Australia | H13: Oceania | I13: Melbourne | J13: =SUM('[1]read_count_fq.txt'!B12:B13) -> 40391740
A14: 3 | D14: 18 | E14: 5 | F14: AUS.18a_4 | G14: Australia | H14: Oceania | I14: Melbourne | J14: =SUM('[1]read_count_fq.txt'!B22:B23) -> 30745896 | K14: =SUM(J10:J14) -> 162769358
A15: 4 | B15: 3 | C15: 4 | D15: 70 | E15: 1 | F15: AUT.70 | G15: Austria | H15: Europe | I15: Vienna | J15: =SUM('[1]read_count_fq.txt'!B34:B35) -> 43517704
A16: 4 | D16: 70 | E16: 2 | F16: AUT.70_1 | G16: Austria | H16: Europe | I16: Vienna | J16: =SUM('[1]read_count_fq.txt'!B28:B29) -> 27412452
A17: 4 | D17: 70 | E17: 3 | F17: AUT.70_2 | G17: Austria | H17: Europe | I17: Vienna | J17: =SUM('[1]read_count_fq.txt'!B30:B31) -> 11587906
A18: 4 | D18: 70 | E18: 4 | F18: AUT.70_3 | G18: Austria | H18: Europe | I18: Vienna | J18: =SUM('[1]read_count_fq.txt'!B32:B33) -> 40087410 | K18: =SUM(J15:J18) -> 122605472
A19: 5 | B19: 4 | C19: 5 | D19: 66 | E19: 1 | F19: BGR.66 | G19: Bulgaria | H19: Europe | I19: Sofia | J19: =SUM('[1]read_count_fq.txt'!B42:B43) -> 50855150
A20: 5 | D20: 66 | E20: 2 | F20: BGR.66_1 | G20: Bulgaria | H20: Europe | I20: Sofia | J20: =SUM('[1]read_count_fq.txt'!B36:B37) -> 33651832
A21: 5 | D21: 66 | E21: 3 | F21: BGR.66_2 | G21: Bulgaria | H21: Europe | I21: Sofia | J21: =SUM('[1]read_count_fq.txt'!B38:B39) -> 14442904
A22: 5 | D22: 66 | E22: 4 | F22: BGR.66_3 | G22: Bulgaria | H22: Europe | I22: Sofia | J22: =SUM('[1]read_count_fq.txt'!B40:B41) -> 45446576 | K22: =SUM(J19:J22) -> 144396462
A23: 6 | B23: 5 | C23: 6 | D23: 53 | E23: 1 | F23: BRA.53 | G23: Brasil | H23: South America | I23: Belem | J23: =SUM('[1]read_count_fq.txt'!B54:B55) -> 46320202
A24: 6 | D24: 53 | E24: 2 | F24: BRA.53_1 | G24: Brasil | H24: South America | I24: Belem | J24: =SUM('[1]read_count_fq.txt'!B44:B45) -> 4499392
A25: 6 | D25: 53 | E25: 3 | F25: BRA.53_2 | G25: Brasil | H25: South America | I25: Belem | J25: =SUM('[1]read_count_fq.txt'!B46:B47) -> 36376794 | K25: =SUM(J23:J25) -> 87196388
A26: 7 | B26: 5 | C26: 6 | D26: 53 | E26: 1 | F26: BRA.53a | G26: Brasil | H26: South America | I26: Belem | J26: =SUM('[1]read_count_fq.txt'!B52:B53) -> 81011902
A27: 7 | D27: 53 | E27: 2 | F27: BRA.53a_1 | G27: Brasil | H27: South America | I27: Belem | J27: =SUM('[1]read_count_fq.txt'!B48:B49) -> 71093118
A28: 7 | D28: 53 | E28: 3 | F28: BRA.53a_2 | G28: Brasil | H28: South America | I28: Belem | J28: =SUM('[1]read_count_fq.txt'!B50:B51) -> 29774494 | K28: =SUM(J26:J28) -> 181879514
A29: 8 | B29: 6 | C29: 7 | D29: 19 | E29: 1 | F29: BWA.19 | G29: Botswana | H29: Africa | I29: Palapye | J29: =SUM('[1]read_count_fq.txt'!B62:B63) -> 41248396
A30: 8 | D30: 19 | E30: 2 | F30: BWA.19_1 | G30: Botswana | H30: Africa | I30: Palapye | J30: =SUM('[1]read_count_fq.txt'!B56:B57) -> 2627960
A31: 8 | D31: 19 | E31: 3 | F31: BWA.19_2 | G31: Botswana | H31: Africa | I31: Palapye | J31: =SUM('[1]read_count_fq.txt'!B58:B59) -> 10958216
A32: 8 | D32: 19 | E32: 4 | F32: BWA.19_3 | G32: Botswana | H32: Africa | I32: Palapye | J32: =SUM('[1]read_count_fq.txt'!B60:B61) -> 42460664 | K32: =SUM(J29:J32) -> 97295236
A33: 9 | B33: 7 | C33: 8 | D33: 22 | E33: 1 | F33: CAN.22 | G33: Canada | H33: North America | I33: Regina | J33: =SUM('[1]read_count_fq.txt'!B90:B91) -> 6248124
A34: 9 | D34: 22 | E34: 2 | F34: CAN.22_1 | G34: Canada | H34: North America | I34: Regina | J34: =SUM('[1]read_count_fq.txt'!B64:B65) -> 1788908
A35: 9 | D35: 22 | E35: 3 | F35: CAN.22_2 | G35: Canada | H35: North America | I35: Regina | J35: =SUM('[1]read_count_fq.txt'!B66:B67) -> 99679622 | K35: =SUM(J33:J35) -> 107716654
A36: 10 | B36: 7 | C36: 9 | D36: 22 | E36: 1 | F36: CAN.22a | G36: Canada | H36: North America | I36: Calgary | J36: =SUM('[1]read_count_fq.txt'!B76:B77) -> 4170118
A37: 10 | D37: 22 | E37: 2 | F37: CAN.22a_1 | G37: Canada | H37: North America | I37: Calgary | J37: =SUM('[1]read_count_fq.txt'!B68:B69) -> 4607878
A38: 10 | D38: 22 | E38: 3 | F38: CAN.22a_2 | G38: Canada | H38: North America | I38: Calgary | J38: =SUM('[1]read_count_fq.txt'!B70:B71) -> 22356330
A39: 10 | D39: 22 | E39: 4 | F39: CAN.22a_3 | G39: Canada | H39: North America | I39: Calgary | J39: =SUM('[1]read_count_fq.txt'!B72:B73) -> 1972064
A40: 10 | D40: 22 | E40: 5 | F40: CAN.22a_4 | G40: Canada | H40: North America | I40: Calgary | J40: =SUM('[1]read_count_fq.txt'!B74:B75) -> 9326308 | K40: =SUM(J36:J40) -> 42432698
...
